Workbook

Sheet Sheet1
A1: ##var | B1: id | C1: name | D1: rarity | E1: pos | F1: basePro | G1: iconName | H1: taoZhuang | I1: des | J1: hidedes | K1: featureDes | L1: itemId | M1: makeCost | N1: tuZhi | O1: qiHuo | P1: upgradeCost | Q1: upgradeProAdd | R1: param | S1: param2
A2: ##type | B2: string | C2: string | D2: string | E2: string | F2: string | G2: string | H2: string | I2: string | J2: string | K2: string | L2: string | M2: string | N2: string | O2: string | P2: string | Q2: string | R2: string | S2: string
A3: ## | B3: id | C3: name | D3: rarity | E3: pos | F3: basePro | G3: iconName | H3: taoZhuang | I3: des | J3: hidedes | K3: featureDes | L3: itemId | M3: makeCost | N3: tuZhi | O3: qiHuo | P3: upgradeCost | Q3: upgradeProAdd | R3: param | S3: param2
B4: 21101 | C4: 结草戒 | D4: 1 | E4: 0 | F4: 10003|435 | G4: ring | I4: 用低阶灵草茎叶编成的法器，灵气微弱，但价格实惠，且容易制作。 | K4: 击中敌人三次后额外回复6点气 | L4: 21101 | M4: 111001|330$10001|1000 | P4: 111001|10$10001|135,111001|57$10001|540,111001|156$10001|1215,111001|320$10001|2160,111001|559$10001|3375,111001|882$10001|4860,111001|1296$10001|6615,111001|1810$10001|8640,111001|2430$10001|10935,111001|3162$10001|13500,111001|4013$10001|16335,111001|4988$10001|19440,111001|6093$10001|22815,111001|7334$10001|26460,111001|8714$10001|30375,111001|10240$10001|34560,111001|11916$10001|39015,111001|13746$10001|43740,111001|15736$10001|48735,111001|17889$10001|54000,111001|20209$10001|59535,111001|22702$10001|65340,111001|25370$10001|71415,111001|28218$10001|77760,111001|31250$10001|84375 | Q4: 65
B5: 21201 | C5: 桃木剑 | D5: 1 | E5: 0 | F5: 10003|435 | G5: sword | I5: 中洲随处可见的低阶法器，由蕴含中正之气的仙桃木制成，对付邪祟格外有效。 | K5: 战斗中暴击率增加20% | L5: 21201 | M5: 111001|330$10001|1000 | P5: 111001|10$10001|135,111001|57$10001|540,111001|156$10001|1215,111001|320$10001|2160,111001|559$10001|3375,111001|882$10001|4860,111001|1296$10001|6615,111001|1810$10001|8640,111001|2430$10001|10935,111001|3162$10001|13500,111001|4013$10001|16335,111001|4988$10001|19440,111001|6093$10001|22815,111001|7334$10001|26460,111001|8714$10001|30375,111001|10240$10001|34560,111001|11916$10001|39015,111001|13746$10001|43740,111001|15736$10001|48735,111001|17889$10001|54000,111001|20209$10001|59535,111001|22702$10001|65340,111001|25370$10001|71415,111001|28218$10001|77760,111001|31250$10001|84375 | Q5: 65
B6: 22101 | C6: 琉璃戒 | D6: 2 | E6: 0 | F6: 10003|521 | G6: ring | I6: 此戒通体雪白，以天山白玉所铸，不留丝毫暗影，故得名沉影。 | K6: 击中敌人两次后额外回复5点气 | L6: 22101 | M6: 112001|430$10001|1500 | P6: 112001|20$10001|270,112001|114$10001|1080,112001|312$10001|2430,112001|640$10001|4320,112001|1118$10001|6750,112001|1764$10001|9720,112001|2592$10001|13230,112001|3620$10001|17280,112001|4860$10001|21870,112001|6324$10001|27000,112001|8026$10001|32670,112001|9976$10001|38880,112001|12186$10001|45630,112001|14668$10001|52920,112001|17428$10001|60750,112001|20480$10001|69120,112001|23832$10001|78030,112001|27492$10001|87480,112001|31472$10001|97470,112001|35778$10001|108000,112001|40418$10001|119070,112001|45404$10001|130680,112001|50740$10001|142830,112001|56436$10001|155520,112001|62500$10001|168750 | Q6: 78
B7: 22201 | C7: 承影剑 | D7: 2 | E7: 0 | F7: 10003|521 | G7: sword | I7: 上古十大名剑之一，传说剑柄与剑身不可同时见，只有在昼夜交替那一刹，方可一窥此剑全貌。 | K7: 击中敌人三次后额外再触发一次攻击 | L7: 22201 | M7: 112001|430$10001|1500 | P7: 112001|20$10001|270,112001|114$10001|1080,112001|312$10001|2430,112001|640$10001|4320,112001|1118$10001|6750,112001|1764$10001|9720,112001|2592$10001|13230,112001|3620$10001|17280,112001|4860$10001|21870,112001|6324$10001|27000,112001|8026$10001|32670,112001|9976$10001|38880,112001|12186$10001|45630,112001|14668$10001|52920,112001|17428$10001|60750,112001|20480$10001|69120,112001|23832$10001|78030,112001|27492$10001|87480,112001|31472$10001|97470,112001|35778$10001|108000,112001|40418$10001|119070,112001|45404$10001|130680,112001|50740$10001|142830,112001|56436$10001|155520,112001|62500$10001|168750 | Q7: 78
B8: 23101 | C8: 玉扳指 | D8: 3 | E8: 0 | F8: 10003|608 | G8: ring | I8: 根据江湖小报调查，这玩意是中老年人最爱的饰品之一 | L8: 23101 | M8: 113001|550$10001|2000 | P8: 113001|40$10001|540,113001|228$10001|2160,113001|624$10001|4860,113001|1280$10001|8640,113001|2236$10001|13500,113001|3528$10001|19440,113001|5184$10001|26460,113001|7240$10001|34560,113001|9720$10001|43740,113001|12648$10001|54000,113001|16052$10001|65340,113001|19952$10001|77760,113001|24372$10001|91260,113001|29336$10001|105840,113001|34856$10001|121500,113001|40960$10001|138240,113001|47664$10001|156060,113001|54984$10001|174960,113001|62944$10001|194940,113001|71556$10001|216000,113001|80836$10001|238140,113001|90808$10001|261360,113001|101480$10001|285660,113001|112872$10001|311040,113001|125000$10001|337500 | Q8: 91
B9: 23201 | C9: 龙泉剑 | E9: 0 | F9: 10003|608 | G9: sword | I9: 良工咨嗟叹奇绝，铸得宝剑名龙泉 | L9: 23201 | M9: 113001|550$10001|2000 | P9: 113001|40$10001|540,113001|228$10001|2160,113001|624$10001|4860,113001|1280$10001|8640,113001|2236$10001|13500,113001|3528$10001|19440,113001|5184$10001|26460,113001|7240$10001|34560,113001|9720$10001|43740,113001|12648$10001|54000,113001|16052$10001|65340,113001|19952$10001|77760,113001|24372$10001|91260,113001|29336$10001|105840,113001|34856$10001|121500,113001|40960$10001|138240,113001|47664$10001|156060,113001|54984$10001|174960,113001|62944$10001|194940,113001|71556$10001|216000,113001|80836$10001|238140,113001|90808$10001|261360,113001|101480$10001|285660,113001|112872$10001|311040,113001|125000$10001|337500 | Q9: 91
B10: 24101 | C10: 湛空戒 | D10: 4 | E10: 0 | F10: 10003|695 | G10: ring | I10: 此戒由湛空石所铸，暗含空间规则之力，其威力无人能挡。据说修炼到极致，可徒手划破虚空。 | L10: 24101 | M10: 114001|1100$10001|2500 | P10: 114001|80$10001|1080,114001|456$10001|4320,114001|1248$10001|9720,114001|2560$10001|17280,114001|4472$10001|27000,114001|7056$10001|38880,114001|10368$10001|52920,114001|14480$10001|69120,114001|19440$10001|87480,114001|25296$10001|108000,114001|32104$10001|130680,114001|39904$10001|155520,114001|48744$10001|182520,114001|58672$10001|211680,114001|69712$10001|243000,114001|81920$10001|276480,114001|95328$10001|312120,114001|109968$10001|349920,114001|125888$10001|389880,114001|143112$10001|432000,114001|161672$10001|476280,114001|181616$10001|522720,114001|202960$10001|571320,114001|225744$10001|622080,114001|250000$10001|675000 | Q10: 104
B11: 25101 | C11: 乾坤戒 | D11: 5 | E11: 0 | F11: 10003|869 | G11: ring | I11: 乾坤戒传说是上古神物，外蕴天命，内蕴地理。其威力毁天灭地，招手间可倾覆山海。 | L11: 25101 | M11: 115001|1655$10001|3000 | P11: 115001|160$10001|2160,115001|912$10001|8640,115001|2496$10001|19440,115001|5120$10001|34560,115001|8944$10001|54000,115001|14112$10001|77760,115001|20736$10001|105840,115001|28960$10001|138240,115001|38880$10001|174960,115001|50592$10001|216000,115001|64208$10001|261360,115001|79808$10001|311040,115001|97488$10001|365040,115001|117344$10001|423360,115001|139424$10001|486000,115001|163840$10001|552960,115001|190656$10001|624240,115001|219936$10001|699840,115001|251776$10001|779760,115001|286224$10001|864000,115001|323344$10001|952560,115001|363232$10001|1045440,115001|405920$10001|1142640,115001|451488$10001|1244160,115001|500000$10001|1350000 | Q11: 130
B12: 24201 | C12: 堕仙剑 | D12: 4 | E12: 0 | F12: 10003|720 | G12: img_duoxianjian | I12: 造成伤害时，有10%（每次精炼+2）50几率召唤一把仙剑额外造成一次40%45 50 55 60攻击力无属性伤害 | J12: 造成伤害时，有50%几率召唤一把仙剑额外造成一次40%攻击力无属性伤害 | L12: 24201 | M12: 114001|1100$10001|2500$344001|1 | P12: 114001|80$10001|1080,114001|456$10001|4320,114001|1248$10001|9720,114001|2560$10001|17280,114001|4472$10001|27000,114001|7056$10001|38880,114001|10368$10001|52920,114001|14480$10001|69120,114001|19440$10001|87480,114001|25296$10001|108000,114001|32104$10001|130680,114001|39904$10001|155520,114001|48744$10001|182520,114001|58672$10001|211680,114001|69712$10001|243000,114001|81920$10001|276480,114001|95328$10001|312120,114001|109968$10001|349920,114001|125888$10001|389880,114001|143112$10001|432000,114001|161672$10001|476280,114001|181616$10001|522720,114001|202960$10001|571320,114001|225744$10001|622080,114001|250000$10001|675000 | Q12: 108 | R12: 50$40|45|50|55|60 | S12: 10059
B13: 21001 | C13: 血云刀 | D13: 1 | E13: 0 | F13: 10003|435 | G13: img_duoxianjian | H13: 1 | L13: 21001 | M13: 111001|330$10001|1000$341002|1 | N13: 341002 | O13: 411001 | P13: 111001|10$10001|135,111001|57$10001|540,111001|156$10001|1215,111001|320$10001|2160,111001|559$10001|3375,111001|882$10001|4860,111001|1296$10001|6615,111001|1810$10001|8640,111001|2430$10001|10935,111001|3162$10001|13500,111001|4013$10001|16335,111001|4988$10001|19440,111001|6093$10001|22815,111001|7334$10001|26460,111001|8714$10001|30375,111001|10240$10001|34560,111001|11916$10001|39015,111001|13746$10001|43740,111001|15736$10001|48735,111001|17889$10001|54000,111001|20209$10001|59535,111001|22702$10001|65340,111001|25370$10001|71415,111001|28218$10001|77760,111001|31250$10001|84375 | Q13: 65
B14: 21002 | C14: 血云衣 | D14: 1 | E14: 1 | F14: 10004|303 | G14: img_duoxianjian | H14: 1 | L14: 21002 | M14: 111001|330$10001|1000$341003|1 | N14: 341003 | O14: 411001 | P14: 111001|10$10001|135,111001|57$10001|540,111001|156$10001|1215,111001|320$10001|2160,111001|559$10001|3375,111001|882$10001|4860,111001|1296$10001|6615,111001|1810$10001|8640,111001|2430$10001|10935,111001|3162$10001|13500,111001|4013$10001|16335,111001|4988$10001|19440,111001|6093$10001|22815,111001|7334$10001|26460,111001|8714$10001|30375,111001|10240$10001|34560,111001|11916$10001|39015,111001|13746$10001|43740,111001|15736$10001|48735,111001|17889$10001|54000,111001|20209$10001|59535,111001|22702$10001|65340,111001|25370$10001|71415,111001|28218$10001|77760,111001|31250$10001|84375 | Q14: 46
B15: 21003 | C15: 血云靴 | D15: 1 | E15: 2 | F15: 10001|1610 | G15: img_duoxianjian | H15: 1 | L15: 21003 | M15: 111001|330$10001|1000$341004|1 | N15: 341004 | O15: 411001 | P15: 111001|10$10001|135,111001|57$10001|540,111001|156$10001|1215,111001|320$10001|2160,111001|559$10001|3375,111001|882$10001|4860,111001|1296$10001|6615,111001|1810$10001|8640,111001|2430$10001|10935,111001|3162$10001|13500,111001|4013$10001|16335,111001|4988$10001|19440,111001|6093$10001|22815,111001|7334$10001|26460,111001|8714$10001|30375,111001|10240$10001|34560,111001|11916$10001|39015,111001|13746$10001|43740,111001|15736$10001|48735,111001|17889$10001|54000,111001|20209$10001|59535,111001|22702$10001|65340,111001|25370$10001|71415,111001|28218$10001|77760,111001|31250$10001|84375 | Q15: 242
B16: 21004 | C16: 血云珠 | D16: 1 | E16: 3 | F16: 10009|458 | G16: img_duoxianjian | H16: 1 | L16: 21004 | M16: 111001|330$10001|1000$341005|1 | N16: 341005 | O16: 411001 | P16: 111001|10$10001|135,111001|57$10001|540,111001|156$10001|1215,111001|320$10001|2160,111001|559$10001|3375,111001|882$10001|4860,111001|1296$10001|6615,111001|1810$10001|8640,111001|2430$10001|10935,111001|3162$10001|13500,111001|4013$10001|16335,111001|4988$10001|19440,111001|6093$10001|22815,111001|7334$10001|26460,111001|8714$10001|30375,111001|10240$10001|34560,111001|11916$10001|39015,111001|13746$10001|43740,111001|15736$10001|48735,111001|17889$10001|54000,111001|20209$10001|59535,111001|22702$10001|65340,111001|25370$10001|71415,111001|28218$10001|77760,111001|31250$10001|84375 | Q16: 69
B17: 21005 | C17: 金龙枪 | D17: 1 | E17: 0 | F17: 10003|563 | G17: img_duoxianjian | H17: 2 | L17: 21005 | M17: 111001|330$10001|1000$341006|1 | N17: 341006 | O17: 411002 | P17: 111001|10$10001|135,111001|57$10001|540,111001|156$10001|1215,111001|320$10001|2160,111001|559$10001|3375,111001|882$10001|4860,111001|1296$10001|6615,111001|1810$10001|8640,111001|2430$10001|10935,111001|3162$10001|13500,111001|4013$10001|16335,111001|4988$10001|19440,111001|6093$10001|22815,111001|7334$10001|26460,111001|8714$10001|30375,111001|10240$10001|34560,111001|11916$10001|39015,111001|13746$10001|43740,111001|15736$10001|48735,111001|17889$10001|54000,111001|20209$10001|59535,111001|22702$10001|65340,111001|25370$10001|71415,111001|28218$10001|77760,111001|31250$10001|84375 | Q17: 85
B18: 21006 | C18: 银龙甲 | D18: 1 | E18: 1 | F18: 10004|285 | G18: img_duoxianjian | H18: 2 | L18: 21006 | M18: 111001|330$10001|1000$341007|1 | N18: 341007 | O18: 411002 | P18: 111001|10$10001|135,111001|57$10001|540,111001|156$10001|1215,111001|320$10001|2160,111001|559$10001|3375,111001|882$10001|4860,111001|1296$10001|6615,111001|1810$10001|8640,111001|2430$10001|10935,111001|3162$10001|13500,111001|4013$10001|16335,111001|4988$10001|19440,111001|6093$10001|22815,111001|7334$10001|26460,111001|8714$10001|30375,111001|10240$10001|34560,111001|11916$10001|39015,111001|13746$10001|43740,111001|15736$10001|48735,111001|17889$10001|54000,111001|20209$10001|59535,111001|22702$10001|65340,111001|25370$10001|71415,111001|28218$10001|77760,111001|31250$10001|84375 | Q18: 43
B19: 21007 | C19: 海龙靴 | D19: 1 | E19: 2 | F19: 10001|1502 | G19: img_duoxianjian | H19: 2 | L19: 21007 | M19: 111001|330$10001|1000$341008|1 | N19: 341008 | O19: 411002 | P19: 111001|10$10001|135,111001|57$10001|540,111001|156$10001|1215,111001|320$10001|2160,111001|559$10001|3375,111001|882$10001|4860,111001|1296$10001|6615,111001|1810$10001|8640,111001|2430$10001|10935,111001|3162$10001|13500,111001|4013$10001|16335,111001|4988$10001|19440,111001|6093$10001|22815,111001|7334$10001|26460,111001|8714$10001|30375,111001|10240$10001|34560,111001|11916$10001|39015,111001|13746$10001|43740,111001|15736$10001|48735,111001|17889$10001|54000,111001|20209$10001|59535,111001|22702$10001|65340,111001|25370$10001|71415,111001|28218$10001|77760,111001|31250$10001|84375 | Q19: 226
B20: 21008 | C20: 黑龙珠 | D20: 1 | E20: 3 | F20: 10009|458 | G20: img_duoxianjian | H20: 2 | L20: 21008 | M20: 111001|330$10001|1000$341009|1 | N20: 341009 | O20: 411002 | P20: 111001|10$10001|135,111001|57$10001|540,111001|156$10001|1215,111001|320$10001|2160,111001|559$10001|3375,111001|882$10001|4860,111001|1296$10001|6615,111001|1810$10001|8640,111001|2430$10001|10935,111001|3162$10001|13500,111001|4013$10001|16335,111001|4988$10001|19440,111001|6093$10001|22815,111001|7334$10001|26460,111001|8714$10001|30375,111001|10240$10001|34560,111001|11916$10001|39015,111001|13746$10001|43740,111001|15736$10001|48735,111001|17889$10001|54000,111001|20209$10001|59535,111001|22702$10001|65340,111001|25370$10001|71415,111001|28218$10001|77760,111001|31250$10001|84375 | Q20: 69
B21: 21009 | C21: 神风剑 | D21: 1 | E21: 0 | F21: 10003|505 | G21: img_duoxianjian | H21: 3 | L21: 21009 | M21: 111001|330$10001|1000$341010|1 | N21: 341010 | O21: 411003 | P21: 111001|10$10001|135,111001|57$10001|540,111001|156$10001|1215,111001|320$10001|2160,111001|559$10001|3375,111001|882$10001|4860,111001|1296$10001|6615,111001|1810$10001|8640,111001|2430$10001|10935,111001|3162$10001|13500,111001|4013$10001|16335,111001|4988$10001|19440,111001|6093$10001|22815,111001|7334$10001|26460,111001|8714$10001|30375,111001|10240$10001|34560,111001|11916$10001|39015,111001|13746$10001|43740,111001|15736$10001|48735,111001|17889$10001|54000,111001|20209$10001|59535,111001|22702$10001|65340,111001|25370$10001|71415,111001|28218$10001|77760,111001|31250$10001|84375 | Q21: 76
B22: 21010 | C22: 须弥甲 | D22: 1 | E22: 1 | F22: 10004|285 | G22: img_duoxianjian | H22: 3 | L22: 21010 | M22: 111001|330$10001|1000$341011|1 | N22: 341011 | O22: 411003 | P22: 111001|10$10001|135,111001|57$10001|540,111001|156$10001|1215,111001|320$10001|2160,111001|559$10001|3375,111001|882$10001|4860,111001|1296$10001|6615,111001|1810$10001|8640,111001|2430$10001|10935,111001|3162$10001|13500,111001|4013$10001|16335,111001|4988$10001|19440,111001|6093$10001|22815,111001|7334$10001|26460,111001|8714$10001|30375,111001|10240$10001|34560,111001|11916$10001|39015,111001|13746$10001|43740,111001|15736$10001|48735,111001|17889$10001|54000,111001|20209$10001|59535,111001|22702$10001|65340,111001|25370$10001|71415,111001|28218$10001|77760,111001|31250$10001|84375 | Q22: 43
B23: 21011 | C23: 清风靴 | D23: 1 | E23: 2 | F23: 10001|1418 | G23: img_duoxianjian | H23: 3 | L23: 21011 | M23: 111001|330$10001|1000$341012|1 | N23: 341012 | O23: 411003 | P23: 111001|10$10001|135,111001|57$10001|540,111001|156$10001|1215,111001|320$10001|2160,111001|559$10001|3375,111001|882$10001|4860,111001|1296$10001|6615,111001|1810$10001|8640,111001|2430$10001|10935,111001|3162$10001|13500,111001|4013$10001|16335,111001|4988$10001|19440,111001|6093$10001|22815,111001|7334$10001|26460,111001|8714$10001|30375,111001|10240$10001|34560,111001|11916$10001|39015,111001|13746$10001|43740,111001|15736$10001|48735,111001|17889$10001|54000,111001|20209$10001|59535,111001|22702$10001|65340,111001|25370$10001|71415,111001|28218$10001|77760,111001|31250$10001|84375 | Q23: 213
B24: 21012 | C24: 百仙玉 | D24: 1 | E24: 3 | F24: 10009|458 | G24: img_duoxianjian | H24: 3 | L24: 21012 | M24: 111001|330$10001|1000$341013|1 | N24: 341013 | O24: 411003 | P24: 111001|10$10001|135,111001|57$10001|540,111001|156$10001|1215,111001|320$10001|2160,111001|559$10001|3375,111001|882$10001|4860,111001|1296$10001|6615,111001|1810$10001|8640,111001|2430$10001|10935,111001|3162$10001|13500,111001|4013$10001|16335,111001|4988$10001|19440,111001|6093$10001|22815,111001|7334$10001|26460,111001|8714$10001|30375,111001|10240$10001|34560,111001|11916$10001|39015,111001|13746$10001|43740,111001|15736$10001|48735,111001|17889$10001|54000,111001|20209$10001|59535,111001|22702$10001|65340,111001|25370$10001|71415,111001|28218$10001|77760,111001|31250$10001|84375 | Q24: 69
... B184: 25012 | C184: 万仙轮回玉 | D184: 5 | E184: 3 | F184: 10009|916 | G184: img_duoxianjian | H184: 3 | L184: 25012 | M184: 115001|1655$10001|3000$345013|1 | N184: 345013 | O184: 415003 | P184: 115001|160$10001|2160,115001|912$10001|8640,115001|2496$10001|19440,115001|5120$10001|34560,115001|8944$10001|54000,115001|14112$10001|77760,115001|20736$10001|105840,115001|28960$10001|138240,115001|38880$10001|174960,115001|50592$10001|216000,115001|64208$10001|261360,115001|79808$10001|311040,115001|97488$10001|365040,115001|117344$10001|423360,115001|139424$10001|486000,115001|163840$10001|552960,115001|190656$10001|624240,115001|219936$10001|699840,115001|251776$10001|779760,115001|286224$10001|864000,115001|323344$10001|952560,115001|363232$10001|1045440,115001|405920$10001|1142640,115001|451488$10001|1244160,115001|500000$10001|1350000 | Q184: 137
B185: 25013 | C185: 元始天尊剑 | D185: 5 | E185: 0 | F185: 10003|870 | H185: 4 | L185: 25013 | M185: 115001|1655$10001|3000$345014|1 | N185: 345014 | O185: 415004 | P185: 115001|160$10001|2160,115001|912$10001|8640,115001|2496$10001|19440,115001|5120$10001|34560,115001|8944$10001|54000,115001|14112$10001|77760,115001|20736$10001|105840,115001|28960$10001|138240,115001|38880$10001|174960,115001|50592$10001|216000,115001|64208$10001|261360,115001|79808$10001|311040,115001|97488$10001|365040,115001|117344$10001|423360,115001|139424$10001|486000,115001|163840$10001|552960,115001|190656$10001|624240,115001|219936$10001|699840,115001|251776$10001|779760,115001|286224$10001|864000,115001|323344$10001|952560,115001|363232$10001|1045440,115001|405920$10001|1142640,115001|451488$10001|1244160,115001|500000$10001|1350000 | Q185: 131
B186: 25014 | C186: 元始涅槃甲 | D186: 5 | E186: 1 | F186: 10004|649 | H186: 4 | L186: 25014 | M186: 115001|1655$10001|3000$345015|1 | N186: 345015 | O186: 415004 | P186: 115001|160$10001|2160,115001|912$10001|8640,115001|2496$10001|19440,115001|5120$10001|34560,115001|8944$10001|54000,115001|14112$10001|77760,115001|20736$10001|105840,115001|28960$10001|138240,115001|38880$10001|174960,115001|50592$10001|216000,115001|64208$10001|261360,115001|79808$10001|311040,115001|97488$10001|365040,115001|117344$10001|423360,115001|139424$10001|486000,115001|163840$10001|552960,115001|190656$10001|624240,115001|219936$10001|699840,115001|251776$10001|779760,115001|286224$10001|864000,115001|323344$10001|952560,115001|363232$10001|1045440,115001|405920$10001|1142640,115001|451488$10001|1244160,115001|500000$10001|1350000 | Q186: 97
B187: 25015 | C187: 元始瞬空靴 | D187: 5 | E187: 2 | F187: 10001|3269 | H187: 4 | L187: 25015 | M187: 115001|1655$10001|3000$345016|1 | N187: 345016 | O187: 415004 | P187: 115001|160$10001|2160,115001|912$10001|8640,115001|2496$10001|19440,115001|5120$10001|34560,115001|8944$10001|54000,115001|14112$10001|77760,115001|20736$10001|105840,115001|28960$10001|138240,115001|38880$10001|174960,115001|50592$10001|216000,115001|64208$10001|261360,115001|79808$10001|311040,115001|97488$10001|365040,115001|117344$10001|423360,115001|139424$10001|486000,115001|163840$10001|552960,115001|190656$10001|624240,115001|219936$10001|699840,115001|251776$10001|779760,115001|286224$10001|864000,115001|323344$10001|952560,115001|363232$10001|1045440,115001|405920$10001|1142640,115001|451488$10001|1244160,115001|500000$10001|1350000 | Q187: 490
B188: 25016 | C188: 元始浮屠珠 | D188: 5 | E188: 3 | F188: 10009|916 | H188: 4 | L188: 25016 | M188: 115001|1655$10001|3000$345017|1 | N188: 345017 | O188: 415004 | P188: 115001|160$10001|2160,115001|912$10001|8640,115001|2496$10001|19440,115001|5120$10001|34560,115001|8944$10001|54000,115001|14112$10001|77760,115001|20736$10001|105840,115001|28960$10001|138240,115001|38880$10001|174960,115001|50592$10001|216000,115001|64208$10001|261360,115001|79808$10001|311040,115001|97488$10001|365040,115001|117344$10001|423360,115001|139424$10001|486000,115001|163840$10001|552960,115001|190656$10001|624240,115001|219936$10001|699840,115001|251776$10001|779760,115001|286224$10001|864000,115001|323344$10001|952560,115001|363232$10001|1045440,115001|405920$10001|1142640,115001|451488$10001|1244160,115001|500000$10001|1350000 | Q188: 137
B189: 25017 | C189: 万海玄冥鼎 | D189: 5 | E189: 0 | F189: 10003|640 | H189: 5 | L189: 25017 | M189: 115001|1655$10001|3000$345018|1 | N189: 345018 | O189: 415005 | P189: 115001|160$10001|2160,115001|912$10001|8640,115001|2496$10001|19440,115001|5120$10001|34560,115001|8944$10001|54000,115001|14112$10001|77760,115001|20736$10001|105840,115001|28960$10001|138240,115001|38880$10001|174960,115001|50592$10001|216000,115001|64208$10001|261360,115001|79808$10001|311040,115001|97488$10001|365040,115001|117344$10001|423360,115001|139424$10001|486000,115001|163840$10001|552960,115001|190656$10001|624240,115001|219936$10001|699840,115001|251776$10001|779760,115001|286224$10001|864000,115001|323344$10001|952560,115001|363232$10001|1045440,115001|405920$10001|1142640,115001|451488$10001|1244160,115001|500000$10001|1350000 | Q189: 96
B190: 25018 | C190: 北冥玄武甲 | D190: 5 | E190: 1 | F190: 10004|763 | H190: 5 | L190: 25018 | M190: 115001|1655$10001|3000$345019|1 | N190: 345019 | O190: 415005 | P190: 115001|160$10001|2160,115001|912$10001|8640,115001|2496$10001|19440,115001|5120$10001|34560,115001|8944$10001|54000,115001|14112$10001|77760,115001|20736$10001|105840,115001|28960$10001|138240,115001|38880$10001|174960,115001|50592$10001|216000,115001|64208$10001|261360,115001|79808$10001|311040,115001|97488$10001|365040,115001|117344$10001|423360,115001|139424$10001|486000,115001|163840$10001|552960,115001|190656$10001|624240,115001|219936$10001|699840,115001|251776$10001|779760,115001|286224$10001|864000,115001|323344$10001|952560,115001|363232$10001|1045440,115001|405920$10001|1142640,115001|451488$10001|1244160,115001|500000$10001|1350000 | Q190: 114
B191: 25019 | C191: 巨山开天靴 | D191: 5 | E191: 2 | F191: 10001|3865 | H191: 5 | L191: 25019 | M191: 115001|1655$10001|3000$345020|1 | N191: 345020 | O191: 415005 | P191: 115001|160$10001|2160,115001|912$10001|8640,115001|2496$10001|19440,115001|5120$10001|34560,115001|8944$10001|54000,115001|14112$10001|77760,115001|20736$10001|105840,115001|28960$10001|138240,115001|38880$10001|174960,115001|50592$10001|216000,115001|64208$10001|261360,115001|79808$10001|311040,115001|97488$10001|365040,115001|117344$10001|423360,115001|139424$10001|486000,115001|163840$10001|552960,115001|190656$10001|624240,115001|219936$10001|699840,115001|251776$10001|779760,115001|286224$10001|864000,115001|323344$10001|952560,115001|363232$10001|1045440,115001|405920$10001|1142640,115001|451488$10001|1244160,115001|500000$10001|1350000 | Q191: 580
B192: 25020 | C192: 幻海潮汐珠 | D192: 5 | E192: 3 | F192: 10009|916 | H192: 5 | L192: 25020 | M192: 115001|1655$10001|3000$345021|1 | N192: 345021 | O192: 415005 | P192: 115001|160$10001|2160,115001|912$10001|8640,115001|2496$10001|19440,115001|5120$10001|34560,115001|8944$10001|54000,115001|14112$10001|77760,115001|20736$10001|105840,115001|28960$10001|138240,115001|38880$10001|174960,115001|50592$10001|216000,115001|64208$10001|261360,115001|79808$10001|311040,115001|97488$10001|365040,115001|117344$10001|423360,115001|139424$10001|486000,115001|163840$10001|552960,115001|190656$10001|624240,115001|219936$10001|699840,115001|251776$10001|779760,115001|286224$10001|864000,115001|323344$10001|952560,115001|363232$10001|1045440,115001|405920$10001|1142640,115001|451488$10001|1244160,115001|500000$10001|1350000 | Q192: 137
B193: 25021 | C193: 飞云玉花刀 | D193: 5 | E193: 0 | F193: 10003|880 | H193: 6 | L193: 25021 | M193: 115001|1655$10001|3000$345022|1 | N193: 345022 | O193: 415006 | P193: 115001|160$10001|2160,115001|912$10001|8640,115001|2496$10001|19440,115001|5120$10001|34560,115001|8944$10001|54000,115001|14112$10001|77760,115001|20736$10001|105840,115001|28960$10001|138240,115001|38880$10001|174960,115001|50592$10001|216000,115001|64208$10001|261360,115001|79808$10001|311040,115001|97488$10001|365040,115001|117344$10001|423360,115001|139424$10001|486000,115001|163840$10001|552960,115001|190656$10001|624240,115001|219936$10001|699840,115001|251776$10001|779760,115001|286224$10001|864000,115001|323344$10001|952560,115001|363232$10001|1045440,115001|405920$10001|1142640,115001|451488$10001|1244160,115001|500000$10001|1350000 | Q193: 132
B194: 25022 | C194: 羽化鹤翎衣 | D194: 5 | E194: 1 | F194: 10004|645 | H194: 6 | L194: 25022 | M194: 115001|1655$10001|3000$345023|1 | N194: 345023 | O194: 415006 | P194: 115001|160$10001|2160,115001|912$10001|8640,115001|2496$10001|19440,115001|5120$10001|34560,115001|8944$10001|54000,115001|14112$10001|77760,115001|20736$10001|105840,115001|28960$10001|138240,115001|38880$10001|174960,115001|50592$10001|216000,115001|64208$10001|261360,115001|79808$10001|311040,115001|97488$10001|365040,115001|117344$10001|423360,115001|139424$10001|486000,115001|163840$10001|552960,115001|190656$10001|624240,115001|219936$10001|699840,115001|251776$10001|779760,115001|286224$10001|864000,115001|323344$10001|952560,115001|363232$10001|1045440,115001|405920$10001|1142640,115001|451488$10001|1244160,115001|500000$10001|1350000 | Q194: 97
B195: 25023 | C195: 云卷曼妙靴 | D195: 5 | E195: 2 | F195: 10001|3260 | H195: 6 | L195: 25023 | M195: 115001|1655$10001|3000$345024|1 | N195: 345024 | O195: 415006 | P195: 115001|160$10001|2160,115001|912$10001|8640,115001|2496$10001|19440,115001|5120$10001|34560,115001|8944$10001|54000,115001|14112$10001|77760,115001|20736$10001|105840,115001|28960$10001|138240,115001|38880$10001|174960,115001|50592$10001|216000,115001|64208$10001|261360,115001|79808$10001|311040,115001|97488$10001|365040,115001|117344$10001|423360,115001|139424$10001|486000,115001|163840$10001|552960,115001|190656$10001|624240,115001|219936$10001|699840,115001|251776$10001|779760,115001|286224$10001|864000,115001|323344$10001|952560,115001|363232$10001|1045440,115001|405920$10001|1142640,115001|451488$10001|1244160,115001|500000$10001|1350000 | Q195: 489
B196: 25024 | C196: 红尘飞云坠 | D196: 5 | E196: 3 | F196: 10009|916 | H196: 6 | L196: 25024 | M196: 115001|1655$10001|3000$345025|1 | N196: 345025 | O196: 415006 | P196: 115001|160$10001|2160,115001|912$10001|8640,115001|2496$10001|19440,115001|5120$10001|34560,115001|8944$10001|54000,115001|14112$10001|77760,115001|20736$10001|105840,115001|28960$10001|138240,115001|38880$10001|174960,115001|50592$10001|216000,115001|64208$10001|261360,115001|79808$10001|311040,115001|97488$10001|365040,115001|117344$10001|423360,115001|139424$10001|486000,115001|163840$10001|552960,115001|190656$10001|624240,115001|219936$10001|699840,115001|251776$10001|779760,115001|286224$10001|864000,115001|323344$10001|952560,115001|363232$10001|1045440,115001|405920$10001|1142640,115001|451488$10001|1244160,115001|500000$10001|1350000 | Q196: 137
... B212: 25040 | C212: 洪荒天命珠 | D212: 5 | E212: 3 | F212: 10009|916 | H212: 10 | L212: 25040 | M212: 115001|1655$10001|3000$345041|1 | N212: 345041 | O212: 415010 | P212: 115001|160$10001|2160,115001|912$10001|8640,115001|2496$10001|19440,115001|5120$10001|34560,115001|8944$10001|54000,115001|14112$10001|77760,115001|20736$10001|105840,115001|28960$10001|138240,115001|38880$10001|174960,115001|50592$10001|216000,115001|64208$10001|261360,115001|79808$10001|311040,115001|97488$10001|365040,115001|117344$10001|423360,115001|139424$10001|486000,115001|163840$10001|552960,115001|190656$10001|624240,115001|219936$10001|699840,115001|251776$10001|779760,115001|286224$10001|864000,115001|323344$10001|952560,115001|363232$10001|1045440,115001|405920$10001|1142640,115001|451488$10001|1244160,115001|500000$10001|1350000 | Q212: 137

Sheet 具体套装
A1: 帝血长空刀 | E1: 帝血狂鲸甲 | I1: 帝血纵云靴 | M1: 帝血浮生珠 | Q1: 九转天龙枪 | U1: 云龙亮银甲 | Y1: 四海玉龙靴 | AC1: 黑龙玄牡珠 | AG1: 太上神风剑 | AK1: 玉虚须弥甲 | AO1: 太上清风靴 | AS1: 万仙轮回玉 | AW1: 元始天尊剑 | BA1: 元始涅槃甲 | BE1: 元始瞬空靴 | BI1: 元始浮屠珠 | BM1: 万海玄冥鼎 | BQ1: 北冥玄武甲 | BU1: 巨山开天靴 | BY1: 幻海潮汐珠 | CC1: 飞云玉花刀 | CG1: 羽化鹤翎衣 | CK1: 云卷曼妙靴 | CO1: 红尘飞云坠 | CS1: 月华流光镜 | CW1: 月莹飞仙衣 | DA1: 皓月空照靴 | DE1: 月华枫露珠 | DI1: 乙木长生鼎 | DM1: 万年青木袍 | DQ1: 众生灵功靴 | DU1: 回春木辉珠 | DY1: 不灭玄骨镜 | EC1: 万骨幽冥铠 | EG1: 紫骨宝玉靴 | EK1: 帝骨无相珠 | EO1: 洪荒斩圣枪 | ES1: 洪荒天妖铠 | EW1: 洪荒百战靴 | FA1: 洪荒天命珠
B2: 初始值 | C2: 每级增长 | D2: 每级攻击变化 | F2: 初始值 | G2: 每级增长 | H2: 每级变化 | J2: 初始值 | K2: 每级增长 | L2: 每级变化 | N2: 初始值 | O2: 每级增长 | P2: 每级变化 | R2: 初始值 | S2: 每级增长 | T2: 每级攻击变化 | V2: 初始值 | W2: 每级增长 | X2: 每级变化 | Z2: 初始值 | AA2: 每级增长 | AB2: 每级变化 | AD2: 初始值 | AE2: 每级增长 | AF2: 每级变化 | AH2: 初始值 | AI2: 每级增长 | AJ2: 每级变化 | AL2: 初始值 | AM2: 每级增长 | AN2: 每级变化 | AP2: 初始值 | AQ2: 每级增长 | AR2: 每级变化 | AT2: 初始值 | AU2: 每级增长 | AV2: 每级变化 | AX2: 初始值 | AY2: 每级增长 | AZ2: 每级变化 | BB2: 初始值 | BC2: 每级增长 | BD2: 每级变化 | BF2: 初始值 | BG2: 每级增长 | BH2: 每级变化 | BJ2: 初始值 | BK2: 每级增长 | BL2: 每级变化 | BN2: 初始值 | BO2: 每级增长 | BP2: 每级变化 | BR2: 初始值 | BS2: 每级增长 | BT2: 每级变化 | BV2: 初始值 | BW2: 每级增长 | BX2: 每级变化 | BZ2: 初始值 | CA2: 每级增长 | CB2: 每级变化 | CD2: 初始值 | CE2: 每级增长 | CF2: 每级攻击变化 | CH2: 初始值 | CI2: 每级增长 | CJ2: 每级攻击变化 | CL2: 初始值 | CM2: 每级增长 | CN2: 每级攻击变化 | CP2: 初始值 | CQ2: 每级增长 | CR2: 每级变化 | CT2: 初始值 | CU2: 每级增长 | CV2: 每级变化 | CX2: 初始值 | CY2: 每级增长 | CZ2: 每级变化 | DB2: 初始值 | DC2: 每级增长 | DD2: 每级变化 | DF2: 初始值 | DG2: 每级增长 | DH2: 每级变化 | DJ2: 初始值 | DK2: 每级增长 | DL2: 每级变化 | DN2: 初始值 | DO2: 每级增长 | DP2: 每级变化 | DR2: 初始值 | DS2: 每级增长 | DT2: 每级变化 | DV2: 初始值 | DW2: 每级增长 | DX2: 每级变化 | DZ2: 初始值 | EA2: 每级增长 | EB2: 每级攻击变化 | ED2: 初始值 | EE2: 每级增长 | EF2: 每级攻击变化 | EH2: 初始值 | EI2: 每级增长 | EJ2: 每级攻击变化 | EL2: 初始值 | EM2: 每级增长 | EN2: 每级变化 | EP2: 初始值 | EQ2: 每级增长 | ER2: 每级变化 | ET2: 初始值 | EU2: 每级增长 | EV2: 每级变化 | EX2: 初始值 | EY2: 每级增长 | EZ2: 每级变化 | FB2: 初始值 | FC2: 每级增长 | FD2: 每级变化
A3: 1 | B3: 869 | C3: =ROUND(B3*0.15,0) | D3: =B3+(A3-1)*C3 | E3: 1 | F3: 605 | G3: =ROUND(F3*0.15,0) | H3: =F3+(E3-1)*G3 | I3: 1 | J3: 3220 | K3: =ROUND(J3*0.15,0) | L3: =J3+(I3-1)*K3 | M3: 1 | N3: 916 | O3: =ROUND(N3*0.15,0) | P3: =N3+(M3-1)*O3 | Q3: 1 | R3: 1125 | S3: =ROUND(R3*0.15,0) | T3: =R3+(Q3-1)*S3 | U3: 1 | V3: 569 | W3: =ROUND(V3*0.15,0) | X3: =V3+(U3-1)*W3 | Y3: 1 | Z3: 3004 | AA3: =ROUND(Z3*0.15,0) | AB3: =Z3+(Y3-1)*AA3 | AC3: 1 | AD3: 916 | AE3: =ROUND(AD3*0.15,0) | AF3: =AD3+(AC3-1)*AE3 | AG3: 1 | AH3: 1009 | AI3: =ROUND(AH3*0.15,0) | AJ3: =AH3+(AG3-1)*AI3 | AK3: 1 | AL3: 569 | AM3: =ROUND(AL3*0.15,0) | AN3: =AL3+(AK3-1)*AM3 | AO3: 1 | AP3: 2836 | AQ3: =ROUND(AP3*0.15,0) | AR3: =AP3+(AO3-1)*AQ3 | AS3: 1 | AT3: 916 | AU3: =ROUND(AT3*0.15,0) | AV3: =AT3+(AS3-1)*AU3 | AW3: 1 | AX3: 870 | AY3: =ROUND(AX3*0.15,0) | AZ3: =AX3+(AW3-1)*AY3 | BA3: 1 | BB3: 649 | BC3: =ROUND(BB3*0.15,0) | BD3: =BB3+(BA3-1)*BC3 | BE3: 1 | BF3: 3269 | BG3: =ROUND(BF3*0.15,0) | BH3: =BF3+(BE3-1)*BG3 | BI3: 1 | BJ3: 916 | BK3: =ROUND(BJ3*0.15,0) | BL3: =BJ3+(BI3-1)*BK3 | BM3: 1 | BN3: 640 | BO3: =ROUND(BN3*0.15,0) | BP3: =BN3+(BM3-1)*BO3 | BQ3: 1 | BR3: 763 | BS3: =ROUND(BR3*0.15,0) | BT3: =BR3+(BQ3-1)*BS3 | BU3: 1 | BV3: 3865 | BW3: =ROUND(BV3*0.15,0) | BX3: =BV3+(BU3-1)*BW3 | BY3: 1 | BZ3: 916 | CA3: =ROUND(BZ3*0.15,0) | CB3: =BZ3+(BY3-1)*CA3 | CC3: 1 | CD3: 880 | CE3: =ROUND(CD3*0.15,0) | CF3: =CD3+(CC3-1)*CE3 | CG3: 1 | CH3: 645 | CI3: =ROUND(CH3*0.15,0) | CJ3: =CH3+(CG3-1)*CI3 | CK3: 1 | CL3: 3260 | CM3: =ROUND(CL3*0.15,0) | CN3: =CL3+(CK3-1)*CM3 | CO3: 1 | CP3: 916 | CQ3: =ROUND(CP3*0.15,0) | CR3: =CP3+(CO3-1)*CQ3 | CS3: 1 | CT3: 817 | CU3: =ROUND(CT3*0.15,0) | CV3: =CT3+(CS3-1)*CU3 | CW3: 1 | CX3: 645 | CY3: =ROUND(CX3*0.15,0) | CZ3: =CX3+(CW3-1)*CY3 | DA3: 1 | DB3: 3120 | DC3: =ROUND(DB3*0.15,0) | DD3: =DB3+(DA3-1)*DC3 | DE3: 1 | DF3: 916 | DG3: =ROUND(DF3*0.15,0) | DH3: =DF3+(DE3-1)*DG3 | DI3: 1 | DJ3: 760 | DK3: =ROUND(DJ3*0.15,0) | DL3: =DJ3+(DI3-1)*DK3 | DM3: 1 | DN3: 690 | DO3: =ROUND(DN3*0.15,0) | DP3: =DN3+(DM3-1)*DO3 | DQ3: 1 | DR3: 3930 | DS3: =ROUND(DR3*0.15,0) | DT3: =DR3+(DQ3-1)*DS3 | DU3: 1 | DV3: 916 | DW3: =ROUND(DV3*0.15,0) | DX3: =DV3+(DU3-1)*DW3 | DY3: 1 | DZ3: 880 | EA3: =ROUND(DZ3*0.15,0) | EB3: =DZ3+(DY3-1)*EA3 | EC3: 1 | ED3: 720 | EE3: =ROUND(ED3*0.15,0) | EF3: =ED3+(EC3-1)*EE3 | EG3: 1 | EH3: 3566 | EI3: =ROUND(EH3*0.15,0) | EJ3: =EH3+(EG3-1)*EI3 | EK3: 1 | EL3: 916 | EM3: =ROUND(EL3*0.15,0) | EN3: =EL3+(EK3-1)*EM3 | EO3: 1 | EP3: 1010 | EQ3: =ROUND(EP3*0.15,0) | ER3: =EP3+(EO3-1)*EQ3 | ES3: 1 | ET3: 645 | EU3: =ROUND(ET3*0.15,0) | EV3: =ET3+(ES3-1)*EU3 | EW3: 1 | EX3: 3260 | EY3: =ROUND(EX3*0.15,0) | EZ3: =EX3+(EW3-1)*EY3 | FA3: 1 | FB3: 916 | FC3: =ROUND(FB3*0.15,0) | FD3: =FB3+(FA3-1)*FC3
A4: 2 | B4: =B3 | C4: =C3 | D4: =B4+(A4-1)*C4 | E4: 2 | F4: =F3 | G4: =G3 | H4: =F4+(E4-1)*G4 | I4: 2 | J4: =J3 | K4: =K3 | L4: =J4+(I4-1)*K4 | M4: 2 | N4: =N3 | O4: =O3 | P4: =N4+(M4-1)*O4 | Q4: 2 | R4: =R3 | S4: =S3 | T4: =R4+(Q4-1)*S4 | U4: 2 | V4: =V3 | W4: =W3 | X4: =V4+(U4-1)*W4 | Y4: 2 | Z4: =Z3 | AA4: =AA3 | AB4: =Z4+(Y4-1)*AA4 | AC4: 2 | AD4: =AD3 | AE4: =AE3 | AF4: =AD4+(AC4-1)*AE4 | AG4: 2 | AH4: =AH3 | AI4: =AI3 | AJ4: =AH4+(AG4-1)*AI4 | AK4: 2 | AL4: =AL3 | AM4: =AM3 | AN4: =AL4+(AK4-1)*AM4 | AO4: 2 | AP4: =AP3 | AQ4: =AQ3 | AR4: =AP4+(AO4-1)*AQ4 | AS4: 2 | AT4: =AT3 | AU4: =AU3 | AV4: =AT4+(AS4-1)*AU4 | AW4: 2 | AX4: =AX3 | AY4: =ROUND(AX4*0.15,0) | AZ4: =AX4+(AW4-1)*AY4 | BA4: 2 | BB4: =BB3 | BC4: =BC3 | BD4: =BB4+(BA4-1)*BC4 | BE4: 2 | BF4: =BF3 | BG4: =BG3 | BH4: =BF4+(BE4-1)*BG4 | BI4: 2 | BJ4: =BJ3 | BK4: =BK3 | BL4: =BJ4+(BI4-1)*BK4 | BM4: 2 | BN4: =BN3 | BO4: =BO3 | BP4: =BN4+(BM4-1)*BO4 | BQ4: 2 | BR4: =BR3 | BS4: =BS3 | BT4: =BR4+(BQ4-1)*BS4 | BU4: 2 | BV4: =BV3 | BW4: =BW3 | BX4: =BV4+(BU4-1)*BW4 | BY4: 2 | BZ4: =BZ3 | CA4: =CA3 | CB4: =BZ4+(BY4-1)*CA4 | CC4: 2 | CD4: =CD3 | CE4: =CE3 | CF4: =CD4+(CC4-1)*CE4 | CG4: 2 | CH4: =CH3 | CI4: =CI3 | CJ4: =CH4+(CG4-1)*CI4 | CK4: 2 | CL4: =CL3 | CM4: =CM3 | CN4: =CL4+(CK4-1)*CM4 | CO4: 2 | CP4: =CP3 | CQ4: =CQ3 | CR4: =CP4+(CO4-1)*CQ4 | CS4: 2 | CT4: =CT3 | CU4: =CU3 | CV4: =CT4+(CS4-1)*CU4 | CW4: 2 | CX4: =CX3 | CY4: =CY3 | CZ4: =CX4+(CW4-1)*CY4 | DA4: 2 | DB4: =DB3 | DC4: =DC3 | DD4: =DB4+(DA4-1)*DC4 | DE4: 2 | DF4: =DF3 | DG4: =DG3 | DH4: =DF4+(DE4-1)*DG4 | DI4: 2 | DJ4: =DJ3 | DK4: =DK3 | DL4: =DJ4+(DI4-1)*DK4 | DM4: 2 | DN4: =DN3 | DO4: =DO3 | DP4: =DN4+(DM4-1)*DO4 | DQ4: 2 | DR4: =DR3 | DS4: =DS3 | DT4: =DR4+(DQ4-1)*DS4 | DU4: 2 | DV4: =DV3 | DW4: =DW3 | DX4: =DV4+(DU4-1)*DW4 | DY4: 2 | DZ4: =DZ3 | EA4: =EA3 | EB4: =DZ4+(DY4-1)*EA4 | EC4: 2 | ED4: =ED3 | EE4: =EE3 | EF4: =ED4+(EC4-1)*EE4 | EG4: 2 | EH4: =EH3 | EI4: =EI3 | EJ4: =EH4+(EG4-1)*EI4 | EK4: 2 | EL4: =EL3 | EM4: =EM3 | EN4: =EL4+(EK4-1)*EM4 | EO4: 2 | EP4: =EP3 | EQ4: =EQ3 | ER4: =EP4+(EO4-1)*EQ4 | ES4: 2 | ET4: =ET3 | EU4: =EU3 | EV4: =ET4+(ES4-1)*EU4 | EW4: 2 | EX4: =EX3 | EY4: =EY3 | EZ4: =EX4+(EW4-1)*EY4 | FA4: 2 | FB4: =FB3 | FC4: =FC3 | FD4: =FB4+(FA4-1)*FC4
A5: 3 | B5: =B4 | C5: =C4 | D5: =B5+(A5-1)*C5 | E5: 3 | F5: =F4 | G5: =G4 | H5: =F5+(E5-1)*G5 | I5: 3 | J5: =J4 | K5: =K4 | L5: =J5+(I5-1)*K5 | M5: 3 | N5: =N4 | O5: =O4 | P5: =N5+(M5-1)*O5 | Q5: 3 | R5: =R4 | S5: =S4 | T5: =R5+(Q5-1)*S5 | U5: 3 | V5: =V4 | W5: =W4 | X5: =V5+(U5-1)*W5 | Y5: 3 | Z5: =Z4 | AA5: =AA4 | AB5: =Z5+(Y5-1)*AA5 | AC5: 3 | AD5: =AD4 | AE5: =AE4 | AF5: =AD5+(AC5-1)*AE5 | AG5: 3 | AH5: =AH4 | AI5: =AI4 | AJ5: =AH5+(AG5-1)*AI5 | AK5: 3 | AL5: =AL4 | AM5: =AM4 | AN5: =AL5+(AK5-1)*AM5 | AO5: 3 | AP5: =AP4 | AQ5: =AQ4 | AR5: =AP5+(AO5-1)*AQ5 | AS5: 3 | AT5: =AT4 | AU5: =AU4 | AV5: =AT5+(AS5-1)*AU5 | AW5: 3 | AX5: =AX4 | AY5: =ROUND(AX5*0.15,0) | AZ5: =AX5+(AW5-1)*AY5 | BA5: 3 | BB5: =BB4 | BC5: =BC4 | BD5: =BB5+(BA5-1)*BC5 | BE5: 3 | BF5: =BF4 | BG5: =BG4 | BH5: =BF5+(BE5-1)*BG5 | BI5: 3 | BJ5: =BJ4 | BK5: =BK4 | BL5: =BJ5+(BI5-1)*BK5 | BM5: 3 | BN5: =BN4 | BO5: =BO4 | BP5: =BN5+(BM5-1)*BO5 | BQ5: 3 | BR5: =BR4 | BS5: =BS4 | BT5: =BR5+(BQ5-1)*BS5 | BU5: 3 | BV5: =BV4 | BW5: =BW4 | BX5: =BV5+(BU5-1)*BW5 | BY5: 3 | BZ5: =BZ4 | CA5: =CA4 | CB5: =BZ5+(BY5-1)*CA5 | CC5: 3 | CD5: =CD4 | CE5: =CE4 | CF5: =CD5+(CC5-1)*CE5 | CG5: 3 | CH5: =CH4 | CI5: =CI4 | CJ5: =CH5+(CG5-1)*CI5 | CK5: 3 | CL5: =CL4 | CM5: =CM4 | CN5: =CL5+(CK5-1)*CM5 | CO5: 3 | CP5: =CP4 | CQ5: =CQ4 | CR5: =CP5+(CO5-1)*CQ5 | CS5: 3 | CT5: =CT4 | CU5: =CU4 | CV5: =CT5+(CS5-1)*CU5 | CW5: 3 | CX5: =CX4 | CY5: =CY4 | CZ5: =CX5+(CW5-1)*CY5 | DA5: 3 | DB5: =DB4 | DC5: =DC4 | DD5: =DB5+(DA5-1)*DC5 | DE5: 3 | DF5: =DF4 | DG5: =DG4 | DH5: =DF5+(DE5-1)*DG5 | DI5: 3 | DJ5: =DJ4 | DK5: =DK4 | DL5: =DJ5+(DI5-1)*DK5 | DM5: 3 | DN5: =DN4 | DO5: =DO4 | DP5: =DN5+(DM5-1)*DO5 | DQ5: 3 | DR5: =DR4 | DS5: =DS4 | DT5: =DR5+(DQ5-1)*DS5 | DU5: 3 | DV5: =DV4 | DW5: =DW4 | DX5: =DV5+(DU5-1)*DW5 | DY5: 3 | DZ5: =DZ4 | EA5: =EA4 | EB5: =DZ5+(DY5-1)*EA5 | EC5: 3 | ED5: =ED4 | EE5: =EE4 | EF5: =ED5+(EC5-1)*EE5 | EG5: 3 | EH5: =EH4 | EI5: =EI4 | EJ5: =EH5+(EG5-1)*EI5 | EK5: 3 | EL5: =EL4 | EM5: =EM4 | EN5: =EL5+(EK5-1)*EM5 | EO5: 3 | EP5: =EP4 | EQ5: =EQ4 | ER5: =EP5+(EO5-1)*EQ5 | ES5: 3 | ET5: =ET4 | EU5: =EU4 | EV5: =ET5+(ES5-1)*EU5 | EW5: 3 | EX5: =EX4 | EY5: =EY4 | EZ5: =EX5+(EW5-1)*EY5 | FA5: 3 | FB5: =FB4 | FC5: =FC4 | FD5: =FB5+(FA5-1)*FC5
A6: 4 | B6: =B5 | C6: =C5 | D6: =B6+(A6-1)*C6 | E6: 4 | F6: =F5 | G6: =G5 | H6: =F6+(E6-1)*G6 | I6: 4 | J6: =J5 | K6: =K5 | L6: =J6+(I6-1)*K6 | M6: 4 | N6: =N5 | O6: =O5 | P6: =N6+(M6-1)*O6 | Q6: 4 | R6: =R5 | S6: =S5 | T6: =R6+(Q6-1)*S6 | U6: 4 | V6: =V5 | W6: =W5 | X6: =V6+(U6-1)*W6 | Y6: 4 | Z6: =Z5 | AA6: =AA5 | AB6: =Z6+(Y6-1)*AA6 | AC6: 4 | AD6: =AD5 | AE6: =AE5 | AF6: =AD6+(AC6-1)*AE6 | AG6: 4 | AH6: =AH5 | AI6: =AI5 | AJ6: =AH6+(AG6-1)*AI6 | AK6: 4 | AL6: =AL5 | AM6: =AM5 | AN6: =AL6+(AK6-1)*AM6 | AO6: 4 | AP6: =AP5 | AQ6: =AQ5 | AR6: =AP6+(AO6-1)*AQ6 | AS6: 4 | AT6: =AT5 | AU6: =AU5 | AV6: =AT6+(AS6-1)*AU6 | AW6: 4 | AX6: =AX5 | AY6: =ROUND(AX6*0.15,0) | AZ6: =AX6+(AW6-1)*AY6 | BA6: 4 | BB6: =BB5 | BC6: =BC5 | BD6: =BB6+(BA6-1)*BC6 | BE6: 4 | BF6: =BF5 | BG6: =BG5 | BH6: =BF6+(BE6-1)*BG6 | BI6: 4 | BJ6: =BJ5 | BK6: =BK5 | BL6: =BJ6+(BI6-1)*BK6 | BM6: 4 | BN6: =BN5 | BO6: =BO5 | BP6: =BN6+(BM6-1)*BO6 | BQ6: 4 | BR6: =BR5 | BS6: =BS5 | BT6: =BR6+(BQ6-1)*BS6 | BU6: 4 | BV6: =BV5 | BW6: =BW5 | BX6: =BV6+(BU6-1)*BW6 | BY6: 4 | BZ6: =BZ5 | CA6: =CA5 | CB6: =BZ6+(BY6-1)*CA6 | CC6: 4 | CD6: =CD5 | CE6: =CE5 | CF6: =CD6+(CC6-1)*CE6 | CG6: 4 | CH6: =CH5 | CI6: =CI5 | CJ6: =CH6+(CG6-1)*CI6 | CK6: 4 | CL6: =CL5 | CM6: =CM5 | CN6: =CL6+(CK6-1)*CM6 | CO6: 4 | CP6: =CP5 | CQ6: =CQ5 | CR6: =CP6+(CO6-1)*CQ6 | CS6: 4 | CT6: =CT5 | CU6: =CU5 | CV6: =CT6+(CS6-1)*CU6 | CW6: 4 | CX6: =CX5 | CY6: =CY5 | CZ6: =CX6+(CW6-1)*CY6 | DA6: 4 | DB6: =DB5 | DC6: =DC5 | DD6: =DB6+(DA6-1)*DC6 | DE6: 4 | DF6: =DF5 | DG6: =DG5 | DH6: =DF6+(DE6-1)*DG6 | DI6: 4 | DJ6: =DJ5 | DK6: =DK5 | DL6: =DJ6+(DI6-1)*DK6 | DM6: 4 | DN6: =DN5 | DO6: =DO5 | DP6: =DN6+(DM6-1)*DO6 | DQ6: 4 | DR6: =DR5 | DS6: =DS5 | DT6: =DR6+(DQ6-1)*DS6 | DU6: 4 | DV6: =DV5 | DW6: =DW5 | DX6: =DV6+(DU6-1)*DW6 | DY6: 4 | DZ6: =DZ5 | EA6: =EA5 | EB6: =DZ6+(DY6-1)*EA6 | EC6: 4 | ED6: =ED5 | EE6: =EE5 | EF6: =ED6+(EC6-1)*EE6 | EG6: 4 | EH6: =EH5 | EI6: =EI5 | EJ6: =EH6+(EG6-1)*EI6 | EK6: 4 | EL6: =EL5 | EM6: =EM5 | EN6: =EL6+(EK6-1)*EM6 | EO6: 4 | EP6: =EP5 | EQ6: =EQ5 | ER6: =EP6+(EO6-1)*EQ6 | ES6: 4 | ET6: =ET5 | EU6: =EU5 | EV6: =ET6+(ES6-1)*EU6 | EW6: 4 | EX6: =EX5 | EY6: =EY5 | EZ6: =EX6+(EW6-1)*EY6 | FA6: 4 | FB6: =FB5 | FC6: =FC5 | FD6: =FB6+(FA6-1)*FC6
A7: 5 | B7: =B6 | C7: =C6 | D7: =B7+(A7-1)*C7 | E7: 5 | F7: =F6 | G7: =G6 | H7: =F7+(E7-1)*G7 | I7: 5 | J7: =J6 | K7: =K6 | L7: =J7+(I7-1)*K7 | M7: 5 | N7: =N6 | O7: =O6 | P7: =N7+(M7-1)*O7 | Q7: 5 | R7: =R6 | S7: =S6 | T7: =R7+(Q7-1)*S7 | U7: 5 | V7: =V6 | W7: =W6 | X7: =V7+(U7-1)*W7 | Y7: 5 | Z7: =Z6 | AA7: =AA6 | AB7: =Z7+(Y7-1)*AA7 | AC7: 5 | AD7: =AD6 | AE7: =AE6 | AF7: =AD7+(AC7-1)*AE7 | AG7: 5 | AH7: =AH6 | AI7: =AI6 | AJ7: =AH7+(AG7-1)*AI7 | AK7: 5 | AL7: =AL6 | AM7: =AM6 | AN7: =AL7+(AK7-1)*AM7 | AO7: 5 | AP7: =AP6 | AQ7: =AQ6 | AR7: =AP7+(AO7-1)*AQ7 | AS7: 5 | AT7: =AT6 | AU7: =AU6 | AV7: =AT7+(AS7-1)*AU7 | AW7: 5 | AX7: =AX6 | AY7: =ROUND(AX7*0.15,0) | AZ7: =AX7+(AW7-1)*AY7 | BA7: 5 | BB7: =BB6 | BC7: =BC6 | BD7: =BB7+(BA7-1)*BC7 | BE7: 5 | BF7: =BF6 | BG7: =BG6 | BH7: =BF7+(BE7-1)*BG7 | BI7: 5 | BJ7: =BJ6 | BK7: =BK6 | BL7: =BJ7+(BI7-1)*BK7 | BM7: 5 | BN7: =BN6 | BO7: =BO6 | BP7: =BN7+(BM7-1)*BO7 | BQ7: 5 | BR7: =BR6 | BS7: =BS6 | BT7: =BR7+(BQ7-1)*BS7 | BU7: 5 | BV7: =BV6 | BW7: =BW6 | BX7: =BV7+(BU7-1)*BW7 | BY7: 5 | BZ7: =BZ6 | CA7: =CA6 | CB7: =BZ7+(BY7-1)*CA7 | CC7: 5 | CD7: =CD6 | CE7: =CE6 | CF7: =CD7+(CC7-1)*CE7 | CG7: 5 | CH7: =CH6 | CI7: =CI6 | CJ7: =CH7+(CG7-1)*CI7 | CK7: 5 | CL7: =CL6 | CM7: =CM6 | CN7: =CL7+(CK7-1)*CM7 | CO7: 5 | CP7: =CP6 | CQ7: =CQ6 | CR7: =CP7+(CO7-1)*CQ7 | CS7: 5 | CT7: =CT6 | CU7: =CU6 | CV7: =CT7+(CS7-1)*CU7 | CW7: 5 | CX7: =CX6 | CY7: =CY6 | CZ7: =CX7+(CW7-1)*CY7 | DA7: 5 | DB7: =DB6 | DC7: =DC6 | DD7: =DB7+(DA7-1)*DC7 | DE7: 5 | DF7: =DF6 | DG7: =DG6 | DH7: =DF7+(DE7-1)*DG7 | DI7: 5 | DJ7: =DJ6 | DK7: =DK6 | DL7: =DJ7+(DI7-1)*DK7 | DM7: 5 | DN7: =DN6 | DO7: =DO6 | DP7: =DN7+(DM7-1)*DO7 | DQ7: 5 | DR7: =DR6 | DS7: =DS6 | DT7: =DR7+(DQ7-1)*DS7 | DU7: 5 | DV7: =DV6 | DW7: =DW6 | DX7: =DV7+(DU7-1)*DW7 | DY7: 5 | DZ7: =DZ6 | EA7: =EA6 | EB7: =DZ7+(DY7-1)*EA7 | EC7: 5 | ED7: =ED6 | EE7: =EE6 | EF7: =ED7+(EC7-1)*EE7 | EG7: 5 | EH7: =EH6 | EI7: =EI6 | EJ7: =EH7+(EG7-1)*EI7 | EK7: 5 | EL7: =EL6 | EM7: =EM6 | EN7: =EL7+(EK7-1)*EM7 | EO7: 5 | EP7: =EP6 | EQ7: =EQ6 | ER7: =EP7+(EO7-1)*EQ7 | ES7: 5 | ET7: =ET6 | EU7: =EU6 | EV7: =ET7+(ES7-1)*EU7 | EW7: 5 | EX7: =EX6 | EY7: =EY6 | EZ7: =EX7+(EW7-1)*EY7 | FA7: 5 | FB7: =FB6 | FC7: =FC6 | FD7: =FB7+(FA7-1)*FC7
A8: 6 | B8: =B7 | C8: =C7 | D8: =B8+(A8-1)*C8 | E8: 6 | F8: =F7 | G8: =G7 | H8: =F8+(E8-1)*G8 | I8: 6 | J8: =J7 | K8: =K7 | L8: =J8+(I8-1)*K8 | M8: 6 | N8: =N7 | O8: =O7 | P8: =N8+(M8-1)*O8 | Q8: 6 | R8: =R7 | S8: =S7 | T8: =R8+(Q8-1)*S8 | U8: 6 | V8: =V7 | W8: =W7 | X8: =V8+(U8-1)*W8 | Y8: 6 | Z8: =Z7 | AA8: =AA7 | AB8: =Z8+(Y8-1)*AA8 | AC8: 6 | AD8: =AD7 | AE8: =AE7 | AF8: =AD8+(AC8-1)*AE8 | AG8: 6 | AH8: =AH7 | AI8: =AI7 | AJ8: =AH8+(AG8-1)*AI8 | AK8: 6 | AL8: =AL7 | AM8: =AM7 | AN8: =AL8+(AK8-1)*AM8 | AO8: 6 | AP8: =AP7 | AQ8: =AQ7 | AR8: =AP8+(AO8-1)*AQ8 | AS8: 6 | AT8: =AT7 | AU8: =AU7 | AV8: =AT8+(AS8-1)*AU8 | AW8: 6 | AX8: =AX7 | AY8: =ROUND(AX8*0.15,0) | AZ8: =AX8+(AW8-1)*AY8 | BA8: 6 | BB8: =BB7 | BC8: =BC7 | BD8: =BB8+(BA8-1)*BC8 | BE8: 6 | BF8: =BF7 | BG8: =BG7 | BH8: =BF8+(BE8-1)*BG8 | BI8: 6 | BJ8: =BJ7 | BK8: =BK7 | BL8: =BJ8+(BI8-1)*BK8 | BM8: 6 | BN8: =BN7 | BO8: =BO7 | BP8: =BN8+(BM8-1)*BO8 | BQ8: 6 | BR8: =BR7 | BS8: =BS7 | BT8: =BR8+(BQ8-1)*BS8 | BU8: 6 | BV8: =BV7 | BW8: =BW7 | BX8: =BV8+(BU8-1)*BW8 | BY8: 6 | BZ8: =BZ7 | CA8: =CA7 | CB8: =BZ8+(BY8-1)*CA8 | CC8: 6 | CD8: =CD7 | CE8: =CE7 | CF8: =CD8+(CC8-1)*CE8 | CG8: 6 | CH8: =CH7 | CI8: =CI7 | CJ8: =CH8+(CG8-1)*CI8 | CK8: 6 | CL8: =CL7 | CM8: =CM7 | CN8: =CL8+(CK8-1)*CM8 | CO8: 6 | CP8: =CP7 | CQ8: =CQ7 | CR8: =CP8+(CO8-1)*CQ8 | CS8: 6 | CT8: =CT7 | CU8: =CU7 | CV8: =CT8+(CS8-1)*CU8 | CW8: 6 | CX8: =CX7 | CY8: =CY7 | CZ8: =CX8+(CW8-1)*CY8 | DA8: 6 | DB8: =DB7 | DC8: =DC7 | DD8: =DB8+(DA8-1)*DC8 | DE8: 6 | DF8: =DF7 | DG8: =DG7 | DH8: =DF8+(DE8-1)*DG8 | DI8: 6 | DJ8: =DJ7 | DK8: =DK7 | DL8: =DJ8+(DI8-1)*DK8 | DM8: 6 | DN8: =DN7 | DO8: =DO7 | DP8: =DN8+(DM8-1)*DO8 | DQ8: 6 | DR8: =DR7 | DS8: =DS7 | DT8: =DR8+(DQ8-1)*DS8 | DU8: 6 | DV8: =DV7 | DW8: =DW7 | DX8: =DV8+(DU8-1)*DW8 | DY8: 6 | DZ8: =DZ7 | EA8: =EA7 | EB8: =DZ8+(DY8-1)*EA8 | EC8: 6 | ED8: =ED7 | EE8: =EE7 | EF8: =ED8+(EC8-1)*EE8 | EG8: 6 | EH8: =EH7 | EI8: =EI7 | EJ8: =EH8+(EG8-1)*EI8 | EK8: 6 | EL8: =EL7 | EM8: =EM7 | EN8: =EL8+(EK8-1)*EM8 | EO8: 6 | EP8: =EP7 | EQ8: =EQ7 | ER8: =EP8+(EO8-1)*EQ8 | ES8: 6 | ET8: =ET7 | EU8: =EU7 | EV8: =ET8+(ES8-1)*EU8 | EW8: 6 | EX8: =EX7 | EY8: =EY7 | EZ8: =EX8+(EW8-1)*EY8 | FA8: 6 | FB8: =FB7 | FC8: =FC7 | FD8: =FB8+(FA8-1)*FC8
A9: 7 | B9: =B8 | C9: =C8 | D9: =B9+(A9-1)*C9 | E9: 7 | F9: =F8 | G9: =G8 | H9: =F9+(E9-1)*G9 | I9: 7 | J9: =J8 | K9: =K8 | L9: =J9+(I9-1)*K9 | M9: 7 | N9: =N8 | O9: =O8 | P9: =N9+(M9-1)*O9 | Q9: 7 | R9: =R8 | S9: =S8 | T9: =R9+(Q9-1)*S9 | U9: 7 | V9: =V8 | W9: =W8 | X9: =V9+(U9-1)*W9 | Y9: 7 | Z9: =Z8 | AA9: =AA8 | AB9: =Z9+(Y9-1)*AA9 | AC9: 7 | AD9: =AD8 | AE9: =AE8 | AF9: =AD9+(AC9-1)*AE9 | AG9: 7 | AH9: =AH8 | AI9: =AI8 | AJ9: =AH9+(AG9-1)*AI9 | AK9: 7 | AL9: =AL8 | AM9: =AM8 | AN9: =AL9+(AK9-1)*AM9 | AO9: 7 | AP9: =AP8 | AQ9: =AQ8 | AR9: =AP9+(AO9-1)*AQ9 | AS9: 7 | AT9: =AT8 | AU9: =AU8 | AV9: =AT9+(AS9-1)*AU9 | AW9: 7 | AX9: =AX8 | AY9: =ROUND(AX9*0.15,0) | AZ9: =AX9+(AW9-1)*AY9 | BA9: 7 | BB9: =BB8 | BC9: =BC8 | BD9: =BB9+(BA9-1)*BC9 | BE9: 7 | BF9: =BF8 | BG9: =BG8 | BH9: =BF9+(BE9-1)*BG9 | BI9: 7 | BJ9: =BJ8 | BK9: =BK8 | BL9: =BJ9+(BI9-1)*BK9 | BM9: 7 | BN9: =BN8 | BO9: =BO8 | BP9: =BN9+(BM9-1)*BO9 | BQ9: 7 | BR9: =BR8 | BS9: =BS8 | BT9: =BR9+(BQ9-1)*BS9 | BU9: 7 | BV9: =BV8 | BW9: =BW8 | BX9: =BV9+(BU9-1)*BW9 | BY9: 7 | BZ9: =BZ8 | CA9: =CA8 | CB9: =BZ9+(BY9-1)*CA9 | CC9: 7 | CD9: =CD8 | CE9: =CE8 | CF9: =CD9+(CC9-1)*CE9 | CG9: 7 | CH9: =CH8 | CI9: =CI8 | CJ9: =CH9+(CG9-1)*CI9 | CK9: 7 | CL9: =CL8 | CM9: =CM8 | CN9: =CL9+(CK9-1)*CM9 | CO9: 7 | CP9: =CP8 | CQ9: =CQ8 | CR9: =CP9+(CO9-1)*CQ9 | CS9: 7 | CT9: =CT8 | CU9: =CU8 | CV9: =CT9+(CS9-1)*CU9 | CW9: 7 | CX9: =CX8 | CY9: =CY8 | CZ9: =CX9+(CW9-1)*CY9 | DA9: 7 | DB9: =DB8 | DC9: =DC8 | DD9: =DB9+(DA9-1)*DC9 | DE9: 7 | DF9: =DF8 | DG9: =DG8 | DH9: =DF9+(DE9-1)*DG9 | DI9: 7 | DJ9: =DJ8 | DK9: =DK8 | DL9: =DJ9+(DI9-1)*DK9 | DM9: 7 | DN9: =DN8 | DO9: =DO8 | DP9: =DN9+(DM9-1)*DO9 | DQ9: 7 | DR9: =DR8 | DS9: =DS8 | DT9: =DR9+(DQ9-1)*DS9 | DU9: 7 | DV9: =DV8 | DW9: =DW8 | DX9: =DV9+(DU9-1)*DW9 | DY9: 7 | DZ9: =DZ8 | EA9: =EA8 | EB9: =DZ9+(DY9-1)*EA9 | EC9: 7 | ED9: =ED8 | EE9: =EE8 | EF9: =ED9+(EC9-1)*EE9 | EG9: 7 | EH9: =EH8 | EI9: =EI8 | EJ9: =EH9+(EG9-1)*EI9 | EK9: 7 | EL9: =EL8 | EM9: =EM8 | EN9: =EL9+(EK9-1)*EM9 | EO9: 7 | EP9: =EP8 | EQ9: =EQ8 | ER9: =EP9+(EO9-1)*EQ9 | ES9: 7 | ET9: =ET8 | EU9: =EU8 | EV9: =ET9+(ES9-1)*EU9 | EW9: 7 | EX9: =EX8 | EY9: =EY8 | EZ9: =EX9+(EW9-1)*EY9 | FA9: 7 | FB9: =FB8 | FC9: =FC8 | FD9: =FB9+(FA9-1)*FC9
A10: 8 | B10: =B9 | C10: =C9 | D10: =B10+(A10-1)*C10 | E10: 8 | F10: =F9 | G10: =G9 | H10: =F10+(E10-1)*G10 | I10: 8 | J10: =J9 | K10: =K9 | L10: =J10+(I10-1)*K10 | M10: 8 | N10: =N9 | O10: =O9 | P10: =N10+(M10-1)*O10 | Q10: 8 | R10: =R9 | S10: =S9 | T10: =R10+(Q10-1)*S10 | U10: 8 | V10: =V9 | W10: =W9 | X10: =V10+(U10-1)*W10 | Y10: 8 | Z10: =Z9 | AA10: =AA9 | AB10: =Z10+(Y10-1)*AA10 | AC10: 8 | AD10: =AD9 | AE10: =AE9 | AF10: =AD10+(AC10-1)*AE10 | AG10: 8 | AH10: =AH9 | AI10: =AI9 | AJ10: =AH10+(AG10-1)*AI10 | AK10: 8 | AL10: =AL9 | AM10: =AM9 | AN10: =AL10+(AK10-1)*AM10 | AO10: 8 | AP10: =AP9 | AQ10: =AQ9 | AR10: =AP10+(AO10-1)*AQ10 | AS10: 8 | AT10: =AT9 | AU10: =AU9 | AV10: =AT10+(AS10-1)*AU10 | AW10: 8 | AX10: =AX9 | AY10: =ROUND(AX10*0.15,0) | AZ10: =AX10+(AW10-1)*AY10 | BA10: 8 | BB10: =BB9 | BC10: =BC9 | BD10: =BB10+(BA10-1)*BC10 | BE10: 8 | BF10: =BF9 | BG10: =BG9 | BH10: =BF10+(BE10-1)*BG10 | BI10: 8 | BJ10: =BJ9 | BK10: =BK9 | BL10: =BJ10+(BI10-1)*BK10 | BM10: 8 | BN10: =BN9 | BO10: =BO9 | BP10: =BN10+(BM10-1)*BO10 | BQ10: 8 | BR10: =BR9 | BS10: =BS9 | BT10: =BR10+(BQ10-1)*BS10 | BU10: 8 | BV10: =BV9 | BW10: =BW9 | BX10: =BV10+(BU10-1)*BW10 | BY10: 8 | BZ10: =BZ9 | CA10: =CA9 | CB10: =BZ10+(BY10-1)*CA10 | CC10: 8 | CD10: =CD9 | CE10: =CE9 | CF10: =CD10+(CC10-1)*CE10 | CG10: 8 | CH10: =CH9 | CI10: =CI9 | CJ10: =CH10+(CG10-1)*CI10 | CK10: 8 | CL10: =CL9 | CM10: =CM9 | CN10: =CL10+(CK10-1)*CM10 | CO10: 8 | CP10: =CP9 | CQ10: =CQ9 | CR10: =CP10+(CO10-1)*CQ10 | CS10: 8 | CT10: =CT9 | CU10: =CU9 | CV10: =CT10+(CS10-1)*CU10 | CW10: 8 | CX10: =CX9 | CY10: =CY9 | CZ10: =CX10+(CW10-1)*CY10 | DA10: 8 | DB10: =DB9 | DC10: =DC9 | DD10: =DB10+(DA10-1)*DC10 | DE10: 8 | DF10: =DF9 | DG10: =DG9 | DH10: =DF10+(DE10-1)*DG10 | DI10: 8 | DJ10: =DJ9 | DK10: =DK9 | DL10: =DJ10+(DI10-1)*DK10 | DM10: 8 | DN10: =DN9 | DO10: =DO9 | DP10: =DN10+(DM10-1)*DO10 | DQ10: 8 | DR10: =DR9 | DS10: =DS9 | DT10: =DR10+(DQ10-1)*DS10 | DU10: 8 | DV10: =DV9 | DW10: =DW9 | DX10: =DV10+(DU10-1)*DW10 | DY10: 8 | DZ10: =DZ9 | EA10: =EA9 | EB10: =DZ10+(DY10-1)*EA10 | EC10: 8 | ED10: =ED9 | EE10: =EE9 | EF10: =ED10+(EC10-1)*EE10 | EG10: 8 | EH10: =EH9 | EI10: =EI9 | EJ10: =EH10+(EG10-1)*EI10 | EK10: 8 | EL10: =EL9 | EM10: =EM9 | EN10: =EL10+(EK10-1)*EM10 | EO10: 8 | EP10: =EP9 | EQ10: =EQ9 | ER10: =EP10+(EO10-1)*EQ10 | ES10: 8 | ET10: =ET9 | EU10: =EU9 | EV10: =ET10+(ES10-1)*EU10 | EW10: 8 | EX10: =EX9 | EY10: =EY9 | EZ10: =EX10+(EW10-1)*EY10 | FA10: 8 | FB10: =FB9 | FC10: =FC9 | FD10: =FB10+(FA10-1)*FC10
A11: 9 | B11: =B10 | C11: =C10 | D11: =B11+(A11-1)*C11 | E11: 9 | F11: =F10 | G11: =G10 | H11: =F11+(E11-1)*G11 | I11: 9 | J11: =J10 | K11: =K10 | L11: =J11+(I11-1)*K11 | M11: 9 | N11: =N10 | O11: =O10 | P11: =N11+(M11-1)*O11 | Q11: 9 | R11: =R10 | S11: =S10 | T11: =R11+(Q11-1)*S11 | U11: 9 | V11: =V10 | W11: =W10 | X11: =V11+(U11-1)*W11 | Y11: 9 | Z11: =Z10 | AA11: =AA10 | AB11: =Z11+(Y11-1)*AA11 | AC11: 9 | AD11: =AD10 | AE11: =AE10 | AF11: =AD11+(AC11-1)*AE11 | AG11: 9 | AH11: =AH10 | AI11: =AI10 | AJ11: =AH11+(AG11-1)*AI11 | AK11: 9 | AL11: =AL10 | AM11: =AM10 | AN11: =AL11+(AK11-1)*AM11 | AO11: 9 | AP11: =AP10 | AQ11: =AQ10 | AR11: =AP11+(AO11-1)*AQ11 | AS11: 9 | AT11: =AT10 | AU11: =AU10 | AV11: =AT11+(AS11-1)*AU11 | AW11: 9 | AX11: =AX10 | AY11: =ROUND(AX11*0.15,0) | AZ11: =AX11+(AW11-1)*AY11 | BA11: 9 | BB11: =BB10 | BC11: =BC10 | BD11: =BB11+(BA11-1)*BC11 | BE11: 9 | BF11: =BF10 | BG11: =BG10 | BH11: =BF11+(BE11-1)*BG11 | BI11: 9 | BJ11: =BJ10 | BK11: =BK10 | BL11: =BJ11+(BI11-1)*BK11 | BM11: 9 | BN11: =BN10 | BO11: =BO10 | BP11: =BN11+(BM11-1)*BO11 | BQ11: 9 | BR11: =BR10 | BS11: =BS10 | BT11: =BR11+(BQ11-1)*BS11 | BU11: 9 | BV11: =BV10 | BW11: =BW10 | BX11: =BV11+(BU11-1)*BW11 | BY11: 9 | BZ11: =BZ10 | CA11: =CA10 | CB11: =BZ11+(BY11-1)*CA11 | CC11: 9 | CD11: =CD10 | CE11: =CE10 | CF11: =CD11+(CC11-1)*CE11 | CG11: 9 | CH11: =CH10 | CI11: =CI10 | CJ11: =CH11+(CG11-1)*CI11 | CK11: 9 | CL11: =CL10 | CM11: =CM10 | CN11: =CL11+(CK11-1)*CM11 | CO11: 9 | CP11: =CP10 | CQ11: =CQ10 | CR11: =CP11+(CO11-1)*CQ11 | CS11: 9 | CT11: =CT10 | CU11: =CU10 | CV11: =CT11+(CS11-1)*CU11 | CW11: 9 | CX11: =CX10 | CY11: =CY10 | CZ11: =CX11+(CW11-1)*CY11 | DA11: 9 | DB11: =DB10 | DC11: =DC10 | DD11: =DB11+(DA11-1)*DC11 | DE11: 9 | DF11: =DF10 | DG11: =DG10 | DH11: =DF11+(DE11-1)*DG11 | DI11: 9 | DJ11: =DJ10 | DK11: =DK10 | DL11: =DJ11+(DI11-1)*DK11 | DM11: 9 | DN11: =DN10 | DO11: =DO10 | DP11: =DN11+(DM11-1)*DO11 | DQ11: 9 | DR11: =DR10 | DS11: =DS10 | DT11: =DR11+(DQ11-1)*DS11 | DU11: 9 | DV11: =DV10 | DW11: =DW10 | DX11: =DV11+(DU11-1)*DW11 | DY11: 9 | DZ11: =DZ10 | EA11: =EA10 | EB11: =DZ11+(DY11-1)*EA11 | EC11: 9 | ED11: =ED10 | EE11: =EE10 | EF11: =ED11+(EC11-1)*EE11 | EG11: 9 | EH11: =EH10 | EI11: =EI10 | EJ11: =EH11+(EG11-1)*EI11 | EK11: 9 | EL11: =EL10 | EM11: =EM10 | EN11: =EL11+(EK11-1)*EM11 | EO11: 9 | EP11: =EP10 | EQ11: =EQ10 | ER11: =EP11+(EO11-1)*EQ11 | ES11: 9 | ET11: =ET10 | EU11: =EU10 | EV11: =ET11+(ES11-1)*EU11 | EW11: 9 | EX11: =EX10 | EY11: =EY10 | EZ11: =EX11+(EW11-1)*EY11 | FA11: 9 | FB11: =FB10 | FC11: =FC10 | FD11: =FB11+(FA11-1)*FC11
A12: 10 | B12: =B11 | C12: =C11 | D12: =B12+(A12-1)*C12 | E12: 10 | F12: =F11 | G12: =G11 | H12: =F12+(E12-1)*G12 | I12: 10 | J12: =J11 | K12: =K11 | L12: =J12+(I12-1)*K12 | M12: 10 | N12: =N11 | O12: =O11 | P12: =N12+(M12-1)*O12 | Q12: 10 | R12: =R11 | S12: =S11 | T12: =R12+(Q12-1)*S12 | U12: 10 | V12: =V11 | W12: =W11 | X12: =V12+(U12-1)*W12 | Y12: 10 | Z12: =Z11 | AA12: =AA11 | AB12: =Z12+(Y12-1)*AA12 | AC12: 10 | AD12: =AD11 | AE12: =AE11 | AF12: =AD12+(AC12-1)*AE12 | AG12: 10 | AH12: =AH11 | AI12: =AI11 | AJ12: =AH12+(AG12-1)*AI12 | AK12: 10 | AL12: =AL11 | AM12: =AM11 | AN12: =AL12+(AK12-1)*AM12 | AO12: 10 | AP12: =AP11 | AQ12: =AQ11 | AR12: =AP12+(AO12-1)*AQ12 | AS12: 10 | AT12: =AT11 | AU12: =AU11 | AV12: =AT12+(AS12-1)*AU12 | AW12: 10 | AX12: =AX11 | AY12: =ROUND(AX12*0.15,0) | AZ12: =AX12+(AW12-1)*AY12 | BA12: 10 | BB12: =BB11 | BC12: =BC11 | BD12: =BB12+(BA12-1)*BC12 | BE12: 10 | BF12: =BF11 | BG12: =BG11 | BH12: =BF12+(BE12-1)*BG12 | BI12: 10 | BJ12: =BJ11 | BK12: =BK11 | BL12: =BJ12+(BI12-1)*BK12 | BM12: 10 | BN12: =BN11 | BO12: =BO11 | BP12: =BN12+(BM12-1)*BO12 | BQ12: 10 | BR12: =BR11 | BS12: =BS11 | BT12: =BR12+(BQ12-1)*BS12 | BU12: 10 | BV12: =BV11 | BW12: =BW11 | BX12: =BV12+(BU12-1)*BW12 | BY12: 10 | BZ12: =BZ11 | CA12: =CA11 | CB12: =BZ12+(BY12-1)*CA12 | CC12: 10 | CD12: =CD11 | CE12: =CE11 | CF12: =CD12+(CC12-1)*CE12 | CG12: 10 | CH12: =CH11 | CI12: =CI11 | CJ12: =CH12+(CG12-1)*CI12 | CK12: 10 | CL12: =CL11 | CM12: =CM11 | CN12: =CL12+(CK12-1)*CM12 | CO12: 10 | CP12: =CP11 | CQ12: =CQ11 | CR12: =CP12+(CO12-1)*CQ12 | CS12: 10 | CT12: =CT11 | CU12: =CU11 | CV12: =CT12+(CS12-1)*CU12 | CW12: 10 | CX12: =CX11 | CY12: =CY11 | CZ12: =CX12+(CW12-1)*CY12 | DA12: 10 | DB12: =DB11 | DC12: =DC11 | DD12: =DB12+(DA12-1)*DC12 | DE12: 10 | DF12: =DF11 | DG12: =DG11 | DH12: =DF12+(DE12-1)*DG12 | DI12: 10 | DJ12: =DJ11 | DK12: =DK11 | DL12: =DJ12+(DI12-1)*DK12 | DM12: 10 | DN12: =DN11 | DO12: =DO11 | DP12: =DN12+(DM12-1)*DO12 | DQ12: 10 | DR12: =DR11 | DS12: =DS11 | DT12: =DR12+(DQ12-1)*DS12 | DU12: 10 | DV12: =DV11 | DW12: =DW11 | DX12: =DV12+(DU12-1)*DW12 | DY12: 10 | DZ12: =DZ11 | EA12: =EA11 | EB12: =DZ12+(DY12-1)*EA12 | EC12: 10 | ED12: =ED11 | EE12: =EE11 | EF12: =ED12+(EC12-1)*EE12 | EG12: 10 | EH12: =EH11 | EI12: =EI11 | EJ12: =EH12+(EG12-1)*EI12 | EK12: 10 | EL12: =EL11 | EM12: =EM11 | EN12: =EL12+(EK12-1)*EM12 | EO12: 10 | EP12: =EP11 | EQ12: =EQ11 | ER12: =EP12+(EO12-1)*EQ12 | ES12: 10 | ET12: =ET11 | EU12: =EU11 | EV12: =ET12+(ES12-1)*EU12 | EW12: 10 | EX12: =EX11 | EY12: =EY11 | EZ12: =EX12+(EW12-1)*EY12 | FA12: 10 | FB12: =FB11 | FC12: =FC11 | FD12: =FB12+(FA12-1)*FC12
A13: 11 | B13: =B12 | C13: =C12 | D13: =B13+(A13-1)*C13 | E13: 11 | F13: =F12 | G13: =G12 | H13: =F13+(E13-1)*G13 | I13: 11 | J13: =J12 | K13: =K12 | L13: =J13+(I13-1)*K13 | M13: 11 | N13: =N12 | O13: =O12 | P13: =N13+(M13-1)*O13 | Q13: 11 | R13: =R12 | S13: =S12 | T13: =R13+(Q13-1)*S13 | U13: 11 | V13: =V12 | W13: =W12 | X13: =V13+(U13-1)*W13 | Y13: 11 | Z13: =Z12 | AA13: =AA12 | AB13: =Z13+(Y13-1)*AA13 | AC13: 11 | AD13: =AD12 | AE13: =AE12 | AF13: =AD13+(AC13-1)*AE13 | AG13: 11 | AH13: =AH12 | AI13: =AI12 | AJ13: =AH13+(AG13-1)*AI13 | AK13: 11 | AL13: =AL12 | AM13: =AM12 | AN13: =AL13+(AK13-1)*AM13 | AO13: 11 | AP13: =AP12 | AQ13: =AQ12 | AR13: =AP13+(AO13-1)*AQ13 | AS13: 11 | AT13: =AT12 | AU13: =AU12 | AV13: =AT13+(AS13-1)*AU13 | AW13: 11 | AX13: =AX12 | AY13: =ROUND(AX13*0.15,0) | AZ13: =AX13+(AW13-1)*AY13 | BA13: 11 | BB13: =BB12 | BC13: =BC12 | BD13: =BB13+(BA13-1)*BC13 | BE13: 11 | BF13: =BF12 | BG13: =BG12 | BH13: =BF13+(BE13-1)*BG13 | BI13: 11 | BJ13: =BJ12 | BK13: =BK12 | BL13: =BJ13+(BI13-1)*BK13 | BM13: 11 | BN13: =BN12 | BO13: =BO12 | BP13: =BN13+(BM13-1)*BO13 | BQ13: 11 | BR13: =BR12 | BS13: =BS12 | BT13: =BR13+(BQ13-1)*BS13 | BU13: 11 | BV13: =BV12 | BW13: =BW12 | BX13: =BV13+(BU13-1)*BW13 | BY13: 11 | BZ13: =BZ12 | CA13: =CA12 | CB13: =BZ13+(BY13-1)*CA13 | CC13: 11 | CD13: =CD12 | CE13: =CE12 | CF13: =CD13+(CC13-1)*CE13 | CG13: 11 | CH13: =CH12 | CI13: =CI12 | CJ13: =CH13+(CG13-1)*CI13 | CK13: 11 | CL13: =CL12 | CM13: =CM12 | CN13: =CL13+(CK13-1)*CM13 | CO13: 11 | CP13: =CP12 | CQ13: =CQ12 | CR13: =CP13+(CO13-1)*CQ13 | CS13: 11 | CT13: =CT12 | CU13: =CU12 | CV13: =CT13+(CS13-1)*CU13 | CW13: 11 | CX13: =CX12 | CY13: =CY12 | CZ13: =CX13+(CW13-1)*CY13 | DA13: 11 | DB13: =DB12 | DC13: =DC12 | DD13: =DB13+(DA13-1)*DC13 | DE13: 11 | DF13: =DF12 | DG13: =DG12 | DH13: =DF13+(DE13-1)*DG13 | DI13: 11 | DJ13: =DJ12 | DK13: =DK12 | DL13: =DJ13+(DI13-1)*DK13 | DM13: 11 | DN13: =DN12 | DO13: =DO12 | DP13: =DN13+(DM13-1)*DO13 | DQ13: 11 | DR13: =DR12 | DS13: =DS12 | DT13: =DR13+(DQ13-1)*DS13 | DU13: 11 | DV13: =DV12 | DW13: =DW12 | DX13: =DV13+(DU13-1)*DW13 | DY13: 11 | DZ13: =DZ12 | EA13: =EA12 | EB13: =DZ13+(DY13-1)*EA13 | EC13: 11 | ED13: =ED12 | EE13: =EE12 | EF13: =ED13+(EC13-1)*EE13 | EG13: 11 | EH13: =EH12 | EI13: =EI12 | EJ13: =EH13+(EG13-1)*EI13 | EK13: 11 | EL13: =EL12 | EM13: =EM12 | EN13: =EL13+(EK13-1)*EM13 | EO13: 11 | EP13: =EP12 | EQ13: =EQ12 | ER13: =EP13+(EO13-1)*EQ13 | ES13: 11 | ET13: =ET12 | EU13: =EU12 | EV13: =ET13+(ES13-1)*EU13 | EW13: 11 | EX13: =EX12 | EY13: =EY12 | EZ13: =EX13+(EW13-1)*EY13 | FA13: 11 | FB13: =FB12 | FC13: =FC12 | FD13: =FB13+(FA13-1)*FC13
